Workbook

Sheet 연장근무-제출용
A1: 연 장 근 로 신 청 서
F3: 담 당 | G3: 본부장
A4: =연장근무작성!$A$2 -> 46088
A6: NO. | B6: 성명 | C6: 연장근로(O/T) 신청 사유 | D6: O/T 신청(당일)
D7: 시작 | E7: 종료 | F7: O/T | G7: 본인 서명
A8: =연장근무작성!A5 -> 1 | B8: =연장근무작성!B5 -> 강 승훈 | C8: =연장근무작성!C5 -> 일산 중산점_리뉴얼 오픈파티 | D8: =연장근무작성!D5 -> 0.45833333 | E8: =연장근무작성!E5 -> 0.75 | F8: =연장근무작성!H5 -> 6
A9: =연장근무작성!A6 -> 2 | B9: =연장근무작성!B6 -> 김 휘동 | C9: =연장근무작성!C6 -> 일산 중산점_리뉴얼 오픈파티 | D9: =연장근무작성!D6 -> 0.45833333 | E9: =연장근무작성!E6 -> 0.75 | F9: =연장근무작성!H6 -> 6
A10: =연장근무작성!A7 -> 3 | B10: =연장근무작성!B7 -> 유 윤상 | C10: =연장근무작성!C7 -> 일산 중산점_리뉴얼 오픈파티 | D10: =연장근무작성!D7 -> 0.45833333 | E10: =연장근무작성!E7 -> 0.75 | F10: =연장근무작성!H7 -> 6
A11: =연장근무작성!A8 -> 0 | B11: =연장근무작성!B8 -> 0 | C11: =연장근무작성!C8 -> 0 | D11: =연장근무작성!D8 -> 0 | E11: =연장근무작성!E8 -> 0 | F11: =연장근무작성!H8 -> 0
A12: =연장근무작성!A9 -> 0 | B12: =연장근무작성!B9 -> 0 | C12: =연장근무작성!C9 -> 0 | D12: =연장근무작성!D9 -> 0 | E12: =연장근무작성!E9 -> 0 | F12: =연장근무작성!H9 -> 0
A13: =연장근무작성!A10 -> 0 | B13: =연장근무작성!B10 -> 0 | C13: =연장근무작성!C10 -> 0 | D13: =연장근무작성!D10 -> 0 | E13: =연장근무작성!E10 -> 0 | F13: =연장근무작성!H10 -> 0
A14: =연장근무작성!A11 -> 0 | B14: =연장근무작성!B11 -> 0 | C14: =연장근무작성!C11 -> 0 | D14: =연장근무작성!D11 -> 0 | E14: =연장근무작성!E11 -> 0 | F14: =연장근무작성!H11 -> 0
A15: =연장근무작성!A12 -> 0 | B15: =연장근무작성!B12 -> 0 | C15: =연장근무작성!C12 -> 0 | D15: =연장근무작성!D12 -> 0 | E15: =연장근무작성!E12 -> 0 | F15: =연장근무작성!H12 -> 0
A16: =연장근무작성!A13 -> 0 | B16: =연장근무작성!B13 -> 0 | C16: =연장근무작성!C13 -> 0 | D16: =연장근무작성!D13 -> 0 | E16: =연장근무작성!E13 -> 0 | F16: =IF(연장근무작성!H13=0,"",연장근무작성!H13)
A17: =연장근무작성!A14 -> 0 | B17: =연장근무작성!B14 -> 0 | C17: =연장근무작성!C14 -> 0 | D17: =연장근무작성!D14 -> 0 | E17: =연장근무작성!E14 -> 0 | F17: =연장근무작성!H14 -> 0
A18: =연장근무작성!A15 -> 0 | B18: =연장근무작성!B15 -> 0 | C18: =연장근무작성!C15 -> 0 | D18: =연장근무작성!D15 -> 0 | E18: =연장근무작성!E15 -> 0 | F18: =연장근무작성!H15 -> 0
A19: =연장근무작성!A16 -> 0 | B19: =연장근무작성!B16 -> 0 | C19: =연장근무작성!C16 -> 0 | D19: =연장근무작성!D16 -> 0 | E19: =연장근무작성!E16 -> 0 | F19: =연장근무작성!H16 -> 0
A20: =연장근무작성!A17 -> 0 | B20: =연장근무작성!B17 -> 0 | C20: =연장근무작성!C17 -> 0 | D20: =연장근무작성!D17 -> 0 | E20: =연장근무작성!E17 -> 0 | F20: =연장근무작성!H17 -> 0
A21: =연장근무작성!A18 -> 0 | B21: =연장근무작성!B18 -> 0 | C21: =연장근무작성!C18 -> 0 | D21: =연장근무작성!D18 -> 0 | E21: =연장근무작성!E18 -> 0 | F21: =연장근무작성!H18 -> 0
A22: =연장근무작성!A19 -> 0 | B22: =연장근무작성!B19 -> 0 | C22: =연장근무작성!C19 -> 0 | D22: =연장근무작성!D19 -> 0 | E22: =연장근무작성!E19 -> 0 | F22: =연장근무작성!H19 -> 0
A24: 연 장 근 로 신 청 서
F26: 담 당 | G26: 본부장
A27: =연장근무작성!$A$29 -> 45991
A29: NO. | B29: 성명 | C29: 연장근로(O/T) 신청 사유 | D29: O/T 신청(당일)
D30: 시작 | E30: 종료 | F30: O/T | G30: 본인 서명
A31: =연장근무작성!A32 -> 1 | B31: =연장근무작성!B32 -> 강 승훈 | C31: =연장근무작성!C32 -> 일산 중산점_리뉴얼 오픈파티 | D31: =연장근무작성!D32 -> 0.5 | E31: =연장근무작성!E32 -> 0.75 | F31: =연장근무작성!H32 -> 5
A32: =연장근무작성!A33 -> 2 | B32: =연장근무작성!B33 -> 김 휘동 | C32: =연장근무작성!C33 -> 일산 중산점_리뉴얼 오픈파티 | D32: =연장근무작성!D33 -> 0 | E32: =연장근무작성!E33 -> 0 | F32: =연장근무작성!H33 -> 0
A33: =연장근무작성!A34 -> 3 | B33: =연장근무작성!B34 -> 유 윤상 | C33: =연장근무작성!C34 -> 일산 중산점_리뉴얼 오픈파티 | D33: =연장근무작성!D34 -> 0 | E33: =연장근무작성!E34 -> 0 | F33: =연장근무작성!H34 -> 0
A34: =연장근무작성!A35 -> 0 | B34: =연장근무작성!B35 -> 0 | C34: =연장근무작성!C35 -> 0 | D34: =연장근무작성!D35 -> 0 | E34: =연장근무작성!E35 -> 0 | F34: =연장근무작성!H35 -> 0
A35: =연장근무작성!A36 -> 0 | B35: =연장근무작성!B36 -> 0 | C35: =연장근무작성!C36 -> 0 | D35: =연장근무작성!D36 -> 0 | E35: =연장근무작성!E36 -> 0 | F35: =연장근무작성!H36 -> 0
A36: =연장근무작성!A37 -> 0 | B36: =연장근무작성!B37 -> 0 | C36: =연장근무작성!C37 -> 0 | D36: =연장근무작성!D37 -> 0 | E36: =연장근무작성!E37 -> 0 | F36: =연장근무작성!H37 -> 0
A37: =연장근무작성!A38 -> 0 | B37: =연장근무작성!B38 -> 0 | C37: =연장근무작성!C38 -> 0 | D37: =연장근무작성!D38 -> 0 | E37: =연장근무작성!E38 -> 0 | F37: =연장근무작성!H38 -> 0
A38: =연장근무작성!A39 -> 0 | B38: =연장근무작성!B39 -> 0 | C38: =연장근무작성!C39 -> 0 | D38: =연장근무작성!D39 -> 0 | E38: =연장근무작성!E39 -> 0 | F38: =연장근무작성!H39 -> 0
A39: =연장근무작성!A40 -> 0 | B39: =연장근무작성!B40 -> 0 | C39: =연장근무작성!C40 -> 0 | D39: =연장근무작성!D40 -> 0 | E39: =연장근무작성!E40 -> 0 | F39: =연장근무작성!H40 -> 0
A40: =연장근무작성!A41 -> 0 | B40: =연장근무작성!B41 -> 0 | C40: =연장근무작성!C41 -> 0 | D40: =연장근무작성!D41 -> 0 | E40: =연장근무작성!E41 -> 0 | F40: =연장근무작성!H41 -> 0
A41: =연장근무작성!A42 -> 0 | B41: =연장근무작성!B42 -> 0 | C41: =연장근무작성!C42 -> 0 | D41: =연장근무작성!D42 -> 0 | E41: =연장근무작성!E42 -> 0 | F41: =연장근무작성!H42 -> 0
A42: =연장근무작성!A43 -> 0 | B42: =연장근무작성!B43 -> 0 | C42: =연장근무작성!C43 -> 0 | D42: =연장근무작성!D43 -> 0 | E42: =연장근무작성!E43 -> 0 | F42: =연장근무작성!H43 -> 0
... A45: =연장근무작성!A46 -> 0 | B45: =연장근무작성!B46 -> 0 | C45: =연장근무작성!C46 -> 0 | D45: =연장근무작성!D46 -> 0 | E45: =연장근무작성!E46 -> 0 | F45: =연장근무작성!H46 -> 0

Sheet 연장근무작성
A1: 종 일 연 장 근 로 작 성
A2: 46088 | C2: =CHOOSE(WEEKDAY($A$2,1),"일요일","월요일","화요일","수요일","목요일","금요일","토요일") -> 토요일
A3: NO. | B3: 성명 | C3: 연장근로(O/T) 신청 사유 | D3: O/T 신청(당일)
D4: 시작 | E4: 종료 | F4: 총 근무시간 | G4: 점심시간 | H4: O/T
A5: {=_xlfn.SEQUENCE(COUNTA(B5:B19))} -> 1 | B5: 강 승훈 | C5: 일산 중산점_리뉴얼 오픈파티 | D5: 0.45833333 | E5: 0.75 | F5: =(E5-D5)*24 -> 7 | G5: =AND(D5<=TIME(12,0,0),E5>=TIME(13,0,0)) -> TRUE | H5: =(E5-D5)*24-IF(AND(D5<=TIME(12,0,0),E5>=TIME(13,0,0)),1,0) -> 6
A6: 2 | B6: 김 휘동 | C6: 일산 중산점_리뉴얼 오픈파티 | D6: 0.45833333 | E6: 0.75 | F6: =(E6-D6)*24 -> 7 | G6: =AND(D6<=TIME(12,0,0),E6>=TIME(13,0,0)) -> TRUE | H6: =(E6-D6)*24-IF(AND(D6<=TIME(12,0,0),E6>=TIME(13,0,0)),1,0) -> 6
A7: 3 | B7: 유 윤상 | C7: 일산 중산점_리뉴얼 오픈파티 | D7: 0.45833333 | E7: 0.75 | F7: =(E7-D7)*24 -> 7 | G7: =AND(D7<=TIME(12,0,0),E7>=TIME(13,0,0)) -> TRUE | H7: =(E7-D7)*24-IF(AND(D7<=TIME(12,0,0),E7>=TIME(13,0,0)),1,0) -> 6
F8: =(E8-D8)*24 -> 0 | G8: =AND(D8<=TIME(12,0,0),E8>=TIME(13,0,0)) -> FALSE | H8: =(E8-D8)*24-IF(AND(D8<=TIME(12,0,0),E8>=TIME(13,0,0)),1,0) -> 0
F9: =(E9-D9)*24 -> 0 | G9: =AND(D9<=TIME(12,0,0),E9>=TIME(13,0,0)) -> FALSE | H9: =(E9-D9)*24-IF(AND(D9<=TIME(12,0,0),E9>=TIME(13,0,0)),1,0) -> 0
F10: =(E10-D10)*24 -> 0 | G10: =AND(D10<=TIME(12,0,0),E10>=TIME(13,0,0)) -> FALSE | H10: =(E10-D10)*24-IF(AND(D10<=TIME(12,0,0),E10>=TIME(13,0,0)),1,0) -> 0
F11: =(E11-D11)*24 -> 0 | G11: =AND(D11<=TIME(12,0,0),E11>=TIME(13,0,0)) -> FALSE | H11: =(E11-D11)*24-IF(AND(D11<=TIME(12,0,0),E11>=TIME(13,0,0)),1,0) -> 0
F12: =(E12-D12)*24 -> 0 | G12: =AND(D12<=TIME(12,0,0),E12>=TIME(13,0,0)) -> FALSE | H12: =(E12-D12)*24-IF(AND(D12<=TIME(12,0,0),E12>=TIME(13,0,0)),1,0) -> 0
F13: =(E13-D13)*24 -> 0 | G13: =AND(D13<=TIME(12,0,0),E13>=TIME(13,0,0)) -> FALSE | H13: =(E13-D13)*24-IF(AND(D13<=TIME(12,0,0),E13>=TIME(13,0,0)),1,0) -> 0
F14: =(E14-D14)*24 -> 0 | G14: =AND(D14<=TIME(12,0,0),E14>=TIME(13,0,0)) -> FALSE | H14: =(E14-D14)*24-IF(AND(D14<=TIME(12,0,0),E14>=TIME(13,0,0)),1,0) -> 0
F15: =(E15-D15)*24 -> 0 | G15: =AND(D15<=TIME(12,0,0),E15>=TIME(13,0,0)) -> FALSE | H15: =(E15-D15)*24-IF(AND(D15<=TIME(12,0,0),E15>=TIME(13,0,0)),1,0) -> 0
F16: =(E16-D16)*24 -> 0 | G16: =AND(D16<=TIME(12,0,0),E16>=TIME(13,0,0)) -> FALSE | H16: =(E16-D16)*24-IF(AND(D16<=TIME(12,0,0),E16>=TIME(13,0,0)),1,0) -> 0
F17: =(E17-D17)*24 -> 0 | G17: =AND(D17<=TIME(12,0,0),E17>=TIME(13,0,0)) -> FALSE | H17: =(E17-D17)*24-IF(AND(D17<=TIME(12,0,0),E17>=TIME(13,0,0)),1,0) -> 0
F18: =(E18-D18)*24 -> 0 | G18: =AND(D18<=TIME(12,0,0),E18>=TIME(13,0,0)) -> FALSE | H18: =(E18-D18)*24-IF(AND(D18<=TIME(12,0,0),E18>=TIME(13,0,0)),1,0) -> 0
F19: =(E19-D19)*24 -> 0 | G19: =AND(D19<=TIME(12,0,0),E19>=TIME(13,0,0)) -> FALSE | H19: =(E19-D19)*24-IF(AND(D19<=TIME(12,0,0),E19>=TIME(13,0,0)),1,0) -> 0
A21: **4시간 이상 연장근무할 경우, 점심시간 1시간 제외
A22: **점심시간 1로 표기
A23: **5.5일 근무자= 토요일 수업하는 코치
A24: 토요일 수업 대신 행사 참여 한 경우, 연장 근무 수당 지급 하지 않음
A25: 일요일 행사 참여한 경우, 연장 근무 수당 지급
A26: **연장근로신청서 제출전, 반드시 지급 대상자 여부 확인 후 제출 요망
A28: 종 일 연 장 근 로 작 성
A29: 45991 | C29: =CHOOSE(WEEKDAY($A$29,1),"일요일","월요일","화요일","수요일","목요일","금요일","토요일") -> 일요일
A30: NO. | B30: 성명 | C30: 연장근로(O/T) 신청 사유 | D30: O/T 신청(당일)
D31: 시작 | E31: 종료 | F31: 총 근무시간 | G31: 점심시간 | H31: O/T
A32: {=_xlfn.SEQUENCE(COUNTA(B32:B46))} -> 1 | B32: 강 승훈 | C32: 일산 중산점_리뉴얼 오픈파티 | D32: 0.5 | E32: 0.75 | F32: =(E32-D32)*24 -> 6 | G32: =AND(D32<=TIME(12,0,0),E32>=TIME(13,0,0)) -> TRUE | H32: =(E32-D32)*24-IF(AND(D32<=TIME(12,0,0),E32>=TIME(13,0,0)),1,0) -> 5
A33: 2 | B33: 김 휘동 | C33: 일산 중산점_리뉴얼 오픈파티 | F33: =(E33-D33)*24 -> 0 | G33: =AND(D33<=TIME(12,0,0),E33>=TIME(13,0,0)) -> FALSE | H33: =(E33-D33)*24-IF(AND(D33<=TIME(12,0,0),E33>=TIME(13,0,0)),1,0) -> 0
A34: 3 | B34: 유 윤상 | C34: 일산 중산점_리뉴얼 오픈파티 | F34: =(E34-D34)*24 -> 0 | G34: =AND(D34<=TIME(12,0,0),E34>=TIME(13,0,0)) -> FALSE | H34: =(E34-D34)*24 -> 0
F35: =(E35-D35)*24 -> 0 | G35: =AND(D35<=TIME(12,0,0),E35>=TIME(13,0,0)) -> FALSE | H35: =(E35-D35)*24 -> 0
F36: =(E36-D36)*24 -> 0 | G36: =AND(D36<=TIME(12,0,0),E36>=TIME(13,0,0)) -> FALSE | H36: =(E36-D36)*24-IF(AND(D36<=TIME(12,0,0),E36>=TIME(13,0,0)),1,0) -> 0
F37: =(E37-D37)*24 -> 0 | G37: =AND(D37<=TIME(12,0,0),E37>=TIME(13,0,0)) -> FALSE | H37: =(E37-D37)*24-IF(AND(D37<=TIME(12,0,0),E37>=TIME(13,0,0)),1,0) -> 0
F38: =(E38-D38)*24 -> 0 | G38: =AND(D38<=TIME(12,0,0),E38>=TIME(13,0,0)) -> FALSE | H38: =(E38-D38)*24-IF(AND(D38<=TIME(12,0,0),E38>=TIME(13,0,0)),1,0) -> 0
F39: =(E39-D39)*24 -> 0 | G39: =AND(D39<=TIME(12,0,0),E39>=TIME(13,0,0)) -> FALSE | H39: =(E39-D39)*24-IF(AND(D39<=TIME(12,0,0),E39>=TIME(13,0,0)),1,0) -> 0
F40: =(E40-D40)*24 -> 0 | G40: =AND(D40<=TIME(12,0,0),E40>=TIME(13,0,0)) -> FALSE | H40: =(E40-D40)*24-IF(AND(D40<=TIME(12,0,0),E40>=TIME(13,0,0)),1,0) -> 0
F41: =(E41-D41)*24 -> 0 | G41: =AND(D41<=TIME(12,0,0),E41>=TIME(13,0,0)) -> FALSE | H41: =(E41-D41)*24-IF(AND(D41<=TIME(12,0,0),E41>=TIME(13,0,0)),1,0) -> 0
F42: =(E42-D42)*24 -> 0 | G42: =AND(D42<=TIME(12,0,0),E42>=TIME(13,0,0)) -> FALSE | H42: =(E42-D42)*24-IF(AND(D42<=TIME(12,0,0),E42>=TIME(13,0,0)),1,0) -> 0
...
